<?xml version="1.0" encoding="utf-8"?>
<!-- This URDF was automatically created by SolidWorks to URDF Exporter! Originally created by Stephen Brawner (brawner@gmail.com) 
     Commit Version: 1.6.0-4-g7f85cfe  Build Version: 1.6.7995.38578
     For more information, please see http://wiki.ros.org/sw_urdf_exporter -->
<robot
  name="chitu_max">
  <!-- <mujoco>
    <compiler
        meshdir="../meshes/"
        balanceinertia="true"
        discardvisual="false" />
  </mujoco> -->
  <link
    name="base">
    <inertial>
      <origin
        xyz="0 0.001213 0.001961"
        rpy="0 0 0" />
      <mass
        value="48.793" />
      <inertia
        ixx="0.60683"
        ixy="0"
        ixz="0"
        iyy="2.1429"
        iyz="-0.00013"
        izz="2.5199" />
    </inertial>
    <visual>
      <origin
        xyz="0 0 0"
        rpy="0 0 0" />
      <geometry>
        <mesh
          filename="../meshes/base_link.STL" />
      </geometry>
      <material
        name="">
        <color
          rgba="1 1 1 1" />
      </material>
    </visual>
    <collision>
      <origin
        xyz="0 0 0"
        rpy="0 0 0" />
      <geometry>
        <box size="0.59 0.36 0.18" />
      </geometry>
    </collision>
  </link>
  <joint name="base_imu_joint" type="fixed">
    <origin rpy="0. 0. 0." xyz="0. 0. 0."/>
    <parent link="base"/>
    <child link="base_imu"/>
  </joint>
  <!-- Imu link -->
  <link name="base_imu">
    <inertial>
      <mass value="0.01"/>
      <origin rpy="0 0 0" xyz="0 0 0"/>
      <inertia ixx="0.000001" ixy="0" ixz="0" iyy="0.000001" iyz="0" izz="0.000001"/>
    </inertial>
    <visual>
      <origin rpy="0 0 0" xyz="0 0 0"/>
      <geometry>
        <box size="0.015 0.015 0.004"/>
      </geometry>
    </visual>
    <material name="orange">
      <color rgba="255 108 10 255"/>
    </material>
  </link>
  <gazebo reference="base_imu">
    <material>Gazebo/Orange</material>
  </gazebo>
  <gazebo reference="base_imu_joint">
    <disableFixedJointLumping>true</disableFixedJointLumping>
  </gazebo>
  <link
    name="LF_hip">
    <inertial>
      <origin
        xyz="0.077026 -0.012824 -5E-06"
        rpy="0 0 0" />
      <mass
        value="3.7016" />
      <inertia
        ixx="0.006455"
        ixy="0.000113"
        ixz="-1E-06"
        iyy="0.00924"
        iyz="-1E-06"
        izz="0.007282" />
    </inertial>
    <visual>
      <origin
        xyz="0 0 0"
        rpy="0 0 0" />
      <geometry>
        <mesh
          filename="../meshes/LFpitch_Link.STL" />
      </geometry>
      <material
        name="">
        <color
          rgba="1 1 1 1" />
      </material>
    </visual>
    <collision>
      <origin
        xyz="0.08 0.06 0"
        rpy="1.5707963 0 0" />
      <geometry>
        <cylinder length="0.24" radius="0.06"/>
      </geometry>
    </collision>
  </link>
  <joint
    name="LF_HAA"
    type="revolute">
    <origin
      xyz="0.301 0.10557 0"
      rpy="0 0 0" />
    <parent
      link="base" />
    <child
      link="LF_hip" />
    <axis
      xyz="1 0 0" />
    <limit
      lower="-0.7854"
      upper="0.7854"
      effort="299"
      velocity="9.14" />
  </joint>
  <link
    name="LF_thigh">
    <inertial>
      <origin
        xyz="-0.022096 0.074493 -0.017402"
        rpy="0 0 0" />
      <mass
        value="5.093" />
      <inertia
        ixx="0.027606"
        ixy="0.005177"
        ixz="-0.016578"
        iyy="0.045524"
        iyz="0.00415"
        izz="0.032386" />
    </inertial>
    <visual>
      <origin
        xyz="0 0 0"
        rpy="0 0 0" />
      <geometry>
        <mesh
          filename="../meshes/LFthigh_Link.STL" />
      </geometry>
      <material
        name="">
        <color
          rgba="1 1 1 1" />
      </material>
    </visual>
    <collision>
      <origin
        xyz="-0.165 0.122 -0.12"
        rpy="1.570796 0.9 0" />
      <geometry>
        <box size="0.04 0.23 0.04"/>
      </geometry>
    </collision>
  </link>
  <joint
    name="LF_HFE"
    type="revolute">
    <origin
      xyz="0.0795 0.0272 0"
      rpy="0 0 0" />
    <parent
      link="LF_hip" />
    <child
      link="LF_thigh" />
    <axis
      xyz="0 1 0" />
    <limit
      lower="-2.618"
      upper="2.618"
      effort="299"
      velocity="9.14" />
  </joint>
  <link
    name="LF_calf">
    <inertial>
      <origin
        xyz="0.14378 0.0010131 -0.13544"
        rpy="0 0 0" />
      <mass
        value="0.71704" />
      <inertia
        ixx="0.0107"
        ixy="-5E-06"
        ixz="0.01028"
        iyy="0.021212"
        iyz="5E-06"
        izz="0.010706" />
    </inertial>
    <visual>
      <origin
        xyz="0 0 0"
        rpy="0 0 0" />
      <geometry>
        <mesh
          filename="../meshes/LFcalf_Link.STL" />
      </geometry>
      <material
        name="">
        <color
          rgba="1 1 1 1" />
      </material>
    </visual>
    <collision>
      <origin
        xyz="0.08 0.0 -0.06"
        rpy="0 0.70 0" />
      <geometry>
        <box size="0.26 0.03 0.03"/>
      </geometry>
    </collision>
    <collision>
      <origin
        xyz="0.220 0 -0.195"
        rpy="0 0.9 0" />
      <geometry>
        <!-- <mesh
          filename="../meshes/LF_calf.STL" /> -->
        <box size="0.124 0.03 0.03"/>
      </geometry>
    </collision>
  </link>
  <joint
    name="LF_KFE"
    type="revolute">
    <origin
      xyz="-0.24748 0.12015 -0.24752"
      rpy="0 0 0" />
    <parent
      link="LF_thigh" />
    <child
      link="LF_calf" />
    <axis
      xyz="0 1 0" />
    <limit
      lower="-1.1345"
      upper="0.7854"
      effort="299"
      velocity="9.14" />
  </joint>

  <!-- ========== 虚拟FT传感器链接（左前腿） ========== -->
  <link name="LF_FT_wrist">
    <inertial>
      <origin xyz="0 0 0" rpy="0 0 0" />
      <mass value="0.0001"/>
      <inertia ixx="1e-8" ixy="0" ixz="0" iyy="1e-8" iyz="0" izz="1e-8"/>
    </inertial>
    <visual>
      <origin xyz="0 0 0" rpy="0 0 0"/>
      <geometry><sphere radius="0.0001"/></geometry>
      <material name="ft_sensor">
        <color rgba="1 0 0 0.5"/>
      </material>
    </visual>
  </link>

  <!-- 虚拟关节：用于安装FT传感器 -->
  <joint name="LF_ft_joint" type="fixed">
    <parent link="LF_calf"/>
    <child link="LF_FT_wrist"/>
    <origin xyz="0.275 -0.0 -0.278" rpy="0 0 0"/>
  </joint>

  <link name="LF_FOOT">
    <inertial>
      <origin xyz="0.0 0.0 0.0" rpy="0 0 0" />
      <mass value="0.1" />
      <inertia ixx="3.5e-05" ixy="0" ixz="0" iyy="3.5e-05" iyz="0" izz="3.5e-05" />
    </inertial>
    <visual>
      <origin xyz="0.0 0.0 0.0" rpy="0 0 0" />
      <geometry>
        <sphere radius="0.041" />
      </geometry>
      <material name="">
        <color rgba="0 0.5 1 1" />
      </material>
    </visual>
    <collision>
      <origin xyz="0.0 0.0 0.0" rpy="0 0 0" />
      <geometry>
        <sphere radius="0.041" />
      </geometry>
    </collision>
  </link>

  <!-- 足端连接到虚拟FT链接 -->
  <joint name="LF_foot_fixed" type="fixed" dont_collapse="true">
    <origin xyz="0 0 0" rpy="0 0 0" />
    <parent link="LF_FT_wrist"/>
    <child link="LF_FOOT"/>
  </joint>

  <gazebo reference="LF_foot_fixed">
    <disableFixedJointLumping>true</disableFixedJointLumping>
  </gazebo>

  <!-- 左前腿FT传感器 -->
  <gazebo reference="LF_foot_fixed">
    <sensor name="lf_ft_sensor" type="force_torque">
      <always_on>true</always_on>
      <update_rate>1000</update_rate>
      <visualize>true</visualize>
      <topic>/ft_sensor/lf_wrench</topic>
      <force_torque>
        <noise>
          <type>gaussian</type>
          <force>
            <mean>0</mean>
            <stddev>0.01</stddev>
          </force>
          <torque>
            <mean>0</mean>
            <stddev>0.001</stddev>
          </torque>
        </noise>
      </force_torque>
    </sensor>
  </gazebo>

  <gazebo reference="LF_hip">
    <mu1>0.2</mu1>
    <mu2>0.2</mu2>
    <material>Gazebo/Turquoise</material>
  </gazebo>
  <gazebo reference="LF_thigh">
    <mu1>0.2</mu1>
    <mu2>0.2</mu2>
    <self_collide>0</self_collide>
    <material>Gazebo/Turquoise</material>
    <kp value="1000000.0"/>
    <kd value="100.0"/>
  </gazebo>
  <gazebo reference="LF_calf">
    <mu1>0.3</mu1>
    <mu2>0.3</mu2>
    <self_collide>1</self_collide>
  </gazebo>
  <gazebo reference="LF_FT_wrist">
    <mu1>0.3</mu1>
    <mu2>0.3</mu2>
    <self_collide>0</self_collide>
  </gazebo>
  <gazebo reference="LF_FOOT">
    <mu1>5.5</mu1>
    <mu2>5.5</mu2>
    <self_collide>1</self_collide>
    <material>Gazebo/Turquoise</material>
    <kp>10000000.0</kp>
    <kd>10000.0</kd>
    <maxVel>1.0</maxVel>
    <minDepth>0.001</minDepth>
  </gazebo>

  <link
    name="LH_hip">
    <inertial>
      <origin
        xyz="-0.077026 -0.012824 5E-06"
        rpy="0 0 0" />
      <mass
        value="3.7016" />
      <inertia
        ixx="0.006455"
        ixy="-0.000113"
        ixz="-1E-06"
        iyy="0.00927"
        iyz="1E-06"
        izz="0.007282" />
    </inertial>
    <visual>
      <origin
        xyz="0 0 0"
        rpy="0 0 0" />
      <geometry>
        <mesh
          filename="../meshes/LBpitch_Link.STL" />
      </geometry>
      <material
        name="">
        <color
          rgba="1 1 1 1" />
      </material>
    </visual>
    <collision>
      <origin
        xyz="-0.08 0.06 0"
        rpy="1.5707963 0 0" />
      <geometry>
        <cylinder length="0.24" radius="0.06" />
      </geometry>
    </collision>
  </link>
  <joint
    name="LH_HAA"
    type="revolute">
    <origin
      xyz="-0.301 0.10557 0"
      rpy="0 0 0" />
    <parent
      link="base" />
    <child
      link="LH_hip" />
    <axis
      xyz="1 0 0" />
    <limit
      lower="-0.7854"
      upper="0.7854"
      effort="299"
      velocity="9.14" />
  </joint>
  <link
    name="LH_thigh">
    <inertial>
      <origin
        xyz="-0.022096 0.074493 -0.017402"
        rpy="0 0 0" />
      <mass
        value="5.093" />
      <inertia
        ixx="0.027606"
        ixy="0.005177"
        ixz="-0.016578"
        iyy="0.045524"
        iyz="0.00415"
        izz="0.032386" />
    </inertial>
    <visual>
      <origin
        xyz="0 0 0"
        rpy="0 0 0" />
      <geometry>
        <mesh
          filename="../meshes/LBthigh_Link.STL" />
      </geometry>
      <material
        name="">
        <color
          rgba="1 1 1 1" />
      </material>
    </visual>
    <collision>
      <origin
        xyz="-0.165 0.122 -0.12"
        rpy="1.570796 0.9 0" />
      <geometry>
        <box size="0.04 0.23 0.04" />
      </geometry>
    </collision>
  </link>
  <joint
    name="LH_HFE"
    type="revolute">
    <origin
      xyz="-0.0795 0.0272 0"
      rpy="0 0 0" />
    <parent
      link="LH_hip" />
    <child
      link="LH_thigh" />
    <axis
      xyz="0 1 0" />
    <limit
      lower="-2.618"
      upper="2.618"
      effort="299"
      velocity="9.14" />
  </joint>
  <link
    name="LH_calf">
    <inertial>
      <origin
        xyz="0.14378 0.0012631 -0.13544"
        rpy="0 0 0" />
      <mass
        value="0.71704" />
      <inertia
        ixx="0.0107"
        ixy="-5E-06"
        ixz="0.01028"
        iyy="0.021212"
        iyz="5E-06"
        izz="0.010706" />
    </inertial>
    <visual>
      <origin
        xyz="0 0 0"
        rpy="0 0 0" />
      <geometry>
        <mesh
          filename="../meshes/LBcalf_Link.STL" />
      </geometry>
      <material
        name="">
        <color
          rgba="1 1 1 1" />
      </material>
    </visual>
    <collision>
      <origin
        xyz="0.08 0.0 -0.06"
        rpy="0 0.70 0" />
      <geometry>
        <box size="0.26 0.03 0.03"/>
      </geometry>
    </collision>
    <collision>
      <origin
        xyz="0.220 0 -0.195"
        rpy="0 0.9 0" />
      <geometry>
        <!-- <mesh
          filename="../meshes/LF_calf.STL" /> -->
        <box size="0.124 0.03 0.03"/>
      </geometry>
    </collision>
  </link>
  <joint
    name="LH_KFE"
    type="revolute">
    <origin
      xyz="-0.24748 0.12015 -0.24752"
      rpy="0 0 0" />
    <parent
      link="LH_thigh" />
    <child
      link="LH_calf" />
    <axis
      xyz="0 1 0" />
    <limit
      lower="-1.1345"
      upper="0.7854"
      effort="299"
      velocity="9.14" />
  </joint>

  <!-- ========== 虚拟FT传感器链接（左后腿） ========== -->
  <link name="LH_FT_wrist">
    <inertial>
      <origin xyz="0 0 0" rpy="0 0 0" />
      <mass value="0.0001"/>
      <inertia ixx="1e-8" ixy="0" ixz="0" iyy="1e-8" iyz="0" izz="1e-8"/>
    </inertial>
    <visual>
      <origin xyz="0 0 0" rpy="0 0 0"/>
      <geometry><sphere radius="0.0001"/></geometry>
      <material name="ft_sensor">
        <color rgba="1 0 0 0.5"/>
      </material>
    </visual>
  </link>

  <!-- 虚拟关节：用于安装FT传感器 -->
  <joint name="LH_ft_joint" type="fixed">
    <parent link="LH_calf"/>
    <child link="LH_FT_wrist"/>
    <origin xyz="0.275 -0.0 -0.278" rpy="0 0 0"/>
  </joint>

  <link name="LH_FOOT">
    <inertial>
      <origin xyz="0.0 0.0 0.0" rpy="0 0 0" />
      <mass value="0.1" />
      <inertia ixx="3.5e-05" ixy="0" ixz="0" iyy="3.5e-05" iyz="0" izz="3.5e-05" />
    </inertial>
    <visual>
      <origin xyz="0.0 0.0 0.0" rpy="0 0 0" />
      <geometry>
        <sphere radius="0.041" />
      </geometry>
      <material name="">
        <color rgba="0 0.5 1 1" />
      </material>
    </visual>
    <collision>
      <origin xyz="0.0 0.0 0.0" rpy="0 0 0" />
      <geometry>
        <sphere radius="0.041" />
      </geometry>
    </collision>
  </link>

  <!-- 足端连接到虚拟FT链接 -->
  <joint name="LH_foot_fixed" type="fixed" dont_collapse="true">
    <origin xyz="0 0 0" rpy="0 0 0" />
    <parent link="LH_FT_wrist"/>
    <child link="LH_FOOT"/>
  </joint>

  <gazebo reference="LH_foot_fixed">
    <disableFixedJointLumping>true</disableFixedJointLumping>
  </gazebo>

  <!-- 左后腿FT传感器 -->
  <gazebo reference="LH_foot_fixed">
    <sensor name="lh_ft_sensor" type="force_torque">
      <always_on>true</always_on>
      <update_rate>1000</update_rate>
      <visualize>true</visualize>
      <topic>/ft_sensor/lh_wrench</topic>
      <force_torque>
        <noise>
          <type>gaussian</type>
          <force>
            <mean>0</mean>
            <stddev>0.01</stddev>
          </force>
          <torque>
            <mean>0</mean>
            <stddev>0.001</stddev>
          </torque>
        </noise>
      </force_torque>
    </sensor>
  </gazebo>

  <gazebo reference="LH_hip">
    <mu1>0.2</mu1>
    <mu2>0.2</mu2>
    <material>Gazebo/Turquoise</material>
  </gazebo>
  <gazebo reference="LH_thigh">
    <mu1>0.2</mu1>
    <mu2>0.2</mu2>
    <self_collide>0</self_collide>
    <material>Gazebo/Turquoise</material>
    <kp value="1000000.0"/>
    <kd value="100.0"/>
  </gazebo>
  <gazebo reference="LH_calf">
    <mu1>0.3</mu1>
    <mu2>0.3</mu2>
    <self_collide>1</self_collide>
  </gazebo>
  <gazebo reference="LH_FT_wrist">
    <mu1>0.3</mu1>
    <mu2>0.3</mu2>
    <self_collide>0</self_collide>
  </gazebo>
  <gazebo reference="LH_FOOT">
    <mu1>5.5</mu1>
    <mu2>5.5</mu2>
    <self_collide>1</self_collide>
    <material>Gazebo/Turquoise</material>
    <kp>10000000.0</kp>
    <kd>10000.0</kd>
    <maxVel>1.0</maxVel>
    <minDepth>0.001</minDepth>
  </gazebo>

  <link
    name="RF_hip">
    <inertial>
      <origin
        xyz="0.077026 0.012824 5E-06"
        rpy="0 0 0" />
      <mass
        value="3.7016" />
      <inertia
        ixx="0.006455"
        ixy="-0.000113"
        ixz="1E-06"
        iyy="0.00924"
        iyz="-1E-06"
        izz="0.007282" />
    </inertial>
    <visual>
      <origin
        xyz="0 0 0"
        rpy="0 0 0" />
      <geometry>
        <mesh
          filename="../meshes/RFpitch_Link.STL" />
      </geometry>
      <material
        name="">
        <color
          rgba="1 1 1 1" />
      </material>
    </visual>
    <collision>
      <origin
        xyz="0.08 -0.06 0"
        rpy="1.5707963 0 0" />
      <geometry>
        <cylinder length="0.24" radius="0.06"/>
      </geometry>
    </collision>
  </link>
  <joint
    name="RF_HAA"
    type="revolute">
    <origin
      xyz="0.301 -0.10557 0"
      rpy="0 0 0" />
    <parent
      link="base" />
    <child
      link="RF_hip" />
    <axis
      xyz="1 0 0" />
    <limit
      lower="-0.7854"
      upper="0.7854"
      effort="299"
      velocity="9.14" />
  </joint>
  <link
    name="RF_thigh">
    <inertial>
      <origin
        xyz="-0.022096 -0.074493 -0.017402"
        rpy="0 0 0" />
      <mass
        value="5.093" />
      <inertia
        ixx="0.027606"
        ixy="-0.005177"
        ixz="-0.016578"
        iyy="0.045524"
        iyz="-0.00415"
        izz="0.032386" />
    </inertial>
    <visual>
      <origin
        xyz="0 0 0"
        rpy="0 0 0" />
      <geometry>
        <mesh
          filename="../meshes/RFthigh_Link.STL" />
      </geometry>
      <material
        name="">
        <color
          rgba="1 1 1 1" />
      </material>
    </visual>
    <collision>
      <origin
        xyz="-0.165 -0.122 -0.12"
        rpy="1.570796 0.9 0" />
      <geometry>
        <box size="0.04 0.23 0.04"/>
      </geometry>
    </collision>
  </link>
  <joint
    name="RF_HFE"
    type="revolute">
    <origin
      xyz="0.0795 -0.0272 0"
      rpy="0 0 0" />
    <parent
      link="RF_hip" />
    <child
      link="RF_thigh" />
    <axis
      xyz="0 1 0" />
    <limit
      lower="-2.618"
      upper="2.618"
      effort="299"
      velocity="9.14" />
  </joint>
  <link
    name="RF_calf">
    <inertial>
      <origin
        xyz="0.14378 -0.000845 -0.13544"
        rpy="0 0 0" />
      <mass
        value="0.71704" />
      <inertia
        ixx="0.0107"
        ixy="-5E-06"
        ixz="0.01028"
        iyy="0.021212"
        iyz="5E-06"
        izz="0.010706" />
    </inertial>
    <visual>
      <origin
        xyz="0 0 0"
        rpy="0 0 0" />
      <geometry>
        <mesh
          filename="../meshes/RFcalf_Link.STL" />
      </geometry>
      <material
        name="">
        <color
          rgba="1 1 1 1" />
      </material>
    </visual>
    <collision>
      <origin
        xyz="0.08 0.0 -0.06"
        rpy="0 0.70 0" />
      <geometry>
        <box size="0.26 0.03 0.03"/>
      </geometry>
    </collision>
    <collision>
      <origin
        xyz="0.220 0 -0.195"
        rpy="0 0.9 0" />
      <geometry>
        <!-- <mesh
          filename="../meshes/LF_calf.STL" /> -->
        <box size="0.124 0.03 0.03"/>
      </geometry>
    </collision>
  </link>
  <joint
    name="RF_KFE"
    type="revolute">
    <origin
      xyz="-0.2475 -0.12015 -0.2475"
      rpy="0 0 0" />
    <parent
      link="RF_thigh" />
    <child
      link="RF_calf" />
    <axis
      xyz="0 1 0" />
    <limit
      lower="-1.1345"
      upper="0.7854"
      effort="299"
      velocity="9.14" />
  </joint>

  <!-- ========== 虚拟FT传感器链接（右前腿） ========== -->
  <link name="RF_FT_wrist">
    <inertial>
      <origin xyz="0 0 0" rpy="0 0 0" />
      <mass value="0.0001"/>
      <inertia ixx="1e-8" ixy="0" ixz="0" iyy="1e-8" iyz="0" izz="1e-8"/>
    </inertial>
    <visual>
      <origin xyz="0 0 0" rpy="0 0 0"/>
      <geometry><sphere radius="0.0001"/></geometry>
      <material name="ft_sensor">
        <color rgba="1 0 0 0.5"/>
      </material>
    </visual>
  </link>

  <!-- 虚拟关节：用于安装FT传感器 -->
  <joint name="RF_ft_joint" type="fixed">
    <parent link="RF_calf"/>
    <child link="RF_FT_wrist"/>
    <origin xyz="0.275 -0.0 -0.278" rpy="0 0 0"/>
  </joint>

  <link name="RF_FOOT">
    <inertial>
      <origin xyz="0.0 0.0 0.0" rpy="0 0 0" />
      <mass value="0.1" />
      <inertia ixx="3.5e-05" ixy="0" ixz="0" iyy="3.5e-05" iyz="0" izz="3.5e-05" />
    </inertial>
    <visual>
      <origin xyz="0.0 0.0 0.0" rpy="0 0 0" />
      <geometry>
        <sphere radius="0.041" />
      </geometry>
      <material name="">
        <color rgba="0 0.5 1 1" />
      </material>
    </visual>
    <collision>
      <origin xyz="0.0 0.0 0.0" rpy="0 0 0" />
      <geometry>
        <sphere radius="0.041" />
      </geometry>
    </collision>
  </link>

  <!-- 足端连接到虚拟FT链接 -->
  <joint name="RF_foot_fixed" type="fixed" dont_collapse="true">
    <origin xyz="0 0 0" rpy="0 0 0" />
    <parent link="RF_FT_wrist"/>
    <child link="RF_FOOT"/>
  </joint>

  <gazebo reference="RF_foot_fixed">
    <disableFixedJointLumping>true</disableFixedJointLumping>
  </gazebo>

  <!-- 右前腿FT传感器 -->
  <gazebo reference="RF_foot_fixed">
    <sensor name="rf_ft_sensor" type="force_torque">
      <always_on>true</always_on>
      <update_rate>1000</update_rate>
      <visualize>true</visualize>
      <topic>/ft_sensor/rf_wrench</topic>
      <force_torque>
        <noise>
          <type>gaussian</type>
          <force>
            <mean>0</mean>
            <stddev>0.01</stddev>
          </force>
          <torque>
            <mean>0</mean>
            <stddev>0.001</stddev>
          </torque>
        </noise>
      </force_torque>
    </sensor>
  </gazebo>

  <gazebo reference="RF_hip">
    <mu1>0.2</mu1>
    <mu2>0.2</mu2>
    <material>Gazebo/Turquoise</material>
  </gazebo>
  <gazebo reference="RF_thigh">
    <mu1>0.2</mu1>
    <mu2>0.2</mu2>
    <self_collide>0</self_collide>
    <material>Gazebo/Turquoise</material>
    <kp value="1000000.0"/>
    <kd value="100.0"/>
  </gazebo>
  <gazebo reference="RF_calf">
    <mu1>0.3</mu1>
    <mu2>0.3</mu2>
    <self_collide>1</self_collide>
  </gazebo>
  <gazebo reference="RF_FT_wrist">
    <mu1>0.3</mu1>
    <mu2>0.3</mu2>
    <self_collide>0</self_collide>
  </gazebo>
  <gazebo reference="RF_FOOT">
    <mu1>5.5</mu1>
    <mu2>5.5</mu2>
    <self_collide>1</self_collide>
    <material>Gazebo/Turquoise</material>
    <kp>10000000.0</kp>
    <kd>10000.0</kd>
    <maxVel>1.0</maxVel>
    <minDepth>0.001</minDepth>
  </gazebo>

  <link
    name="RH_hip">
    <inertial>
      <origin
        xyz="-0.077026 0.012824 -5E-05"
        rpy="0 0 0" />
      <mass
        value="3.7016" />
      <inertia
        ixx="0.006455"
        ixy="0.000113"
        ixz="1E-06"
        iyy="0.00924"
        iyz="1E-06"
        izz="0.007282" />
    </inertial>
    <visual>
      <origin
        xyz="0 0 0"
        rpy="0 0 0" />
      <geometry>
        <mesh
          filename="../meshes/RBpitch_Link.STL" />
      </geometry>
      <material
        name="">
        <color
          rgba="1 1 1 1" />
      </material>
    </visual>
    <collision>
      <origin
        xyz="-0.08 -0.06 0"
        rpy="1.5707963 0 0" />
      <geometry>
        <cylinder length="0.24" radius="0.06" />
      </geometry>
    </collision>
  </link>
  <joint
    name="RH_HAA"
    type="revolute">
    <origin
      xyz="-0.301 -0.10557 0"
      rpy="0 0 0" />
    <parent
      link="base" />
    <child
      link="RH_hip" />
    <axis
      xyz="1 0 0" />
    <limit
      lower="-0.7854"
      upper="0.7854"
      effort="299"
      velocity="9.14" />
  </joint>
  <link
    name="RH_thigh">
    <inertial>
      <origin
        xyz="-0.022096 -0.074493 -0.017402"
        rpy="0 0 0" />
      <mass
        value="5.093" />
      <inertia
        ixx="0.027606"
        ixy="-0.005177"
        ixz="-0.016578"
        iyy="0.045524"
        iyz="-0.00415"
        izz="0.032386" />
    </inertial>
    <visual>
      <origin
        xyz="0 0 0"
        rpy="0 0 0" />
      <geometry>
        <mesh
          filename="../meshes/RBthigh_Link.STL" />
      </geometry>
      <material
        name="">
        <color
          rgba="1 1 1 1" />
      </material>
    </visual>
    <collision>
      <origin
        xyz="-0.165 -0.122 -0.12"
        rpy="1.570796 0.9 0" />
      <geometry>
        <box size="0.04 0.23 0.04" />
      </geometry>
    </collision>
  </link>
  <joint
    name="RH_HFE"
    type="revolute">
    <origin
      xyz="-0.0795 -0.0272 0"
      rpy="0 0 0" />
    <parent
      link="RH_hip" />
    <child
      link="RH_thigh" />
    <axis
      xyz="0 1 0" />
    <limit
      lower="-2.618"
      upper="2.618"
      effort="299"
      velocity="9.14" />
  </joint>
  <link
    name="RH_calf">
    <inertial>
      <origin
        xyz="0.14378 -0.000845 -0.13544"
        rpy="0 0 0" />
      <mass
        value="0.71704" />
      <inertia
        ixx="0.0107"
        ixy="-5E-06"
        ixz="0.01028"
        iyy="0.021212"
        iyz="5E-06"
        izz="0.010706" />
    </inertial>
    <visual>
      <origin
        xyz="0 0 0"
        rpy="0 0 0" />
      <geometry>
        <mesh
          filename="../meshes/RBcalf_Link.STL" />
      </geometry>
      <material
        name="">
        <color
          rgba="1 1 1 1" />
      </material>
    </visual>
    <collision>
      <origin
        xyz="0.08 0.0 -0.06"
        rpy="0 0.70 0" />
      <geometry>
        <box size="0.26 0.03 0.03"/>
      </geometry>
    </collision>
    <collision>
      <origin
        xyz="0.220 0 -0.195"
        rpy="0 0.9 0" />
      <geometry>
        <!-- <mesh
          filename="../meshes/LF_calf.STL" /> -->
        <box size="0.124 0.03 0.03"/>
      </geometry>
    </collision>
  </link>
  <joint
    name="RH_KFE"
    type="revolute">
    <origin
      xyz="-0.24748 -0.12015 -0.24752"
      rpy="0 0 0" />
    <parent
      link="RH_thigh" />
    <child
      link="RH_calf" />
    <axis
      xyz="0 1 0" />
    <limit
      lower="-1.1345"
      upper="0.7854"
      effort="299"
      velocity="9.14" />
  </joint>

  <!-- ========== 虚拟FT传感器链接（右后腿） ========== -->
  <link name="RH_FT_wrist">
    <inertial>
      <origin xyz="0 0 0" rpy="0 0 0" />
      <mass value="0.0001"/>
      <inertia ixx="1e-8" ixy="0" ixz="0" iyy="1e-8" iyz="0" izz="1e-8"/>
    </inertial>
    <visual>
      <origin xyz="0 0 0" rpy="0 0 0"/>
      <geometry><sphere radius="0.0001"/></geometry>
      <material name="ft_sensor">
        <color rgba="1 0 0 0.5"/>
      </material>
    </visual>
  </link>

  <!-- 虚拟关节：用于安装FT传感器 -->
  <joint name="RH_ft_joint" type="fixed">
    <parent link="RH_calf"/>
    <child link="RH_FT_wrist"/>
    <origin xyz="0.275 -0.0 -0.278" rpy="0 0 0"/>
  </joint>

  <link name="RH_FOOT">
    <inertial>
      <origin xyz="0.0 0.0 0.0" rpy="0 0 0" />
      <mass value="0.1" />
      <inertia ixx="3.5e-05" ixy="0" ixz="0" iyy="3.5e-05" iyz="0" izz="3.5e-05" />
    </inertial>
    <visual>
      <origin xyz="0.0 0.0 0.0" rpy="0 0 0" />
      <geometry>
        <sphere radius="0.041" />
      </geometry>
      <material name="">
        <color rgba="0 0.5 1 1" />
      </material>
    </visual>
    <collision>
      <origin xyz="0.0 0.0 0.0" rpy="0 0 0" />
      <geometry>
        <sphere radius="0.041" />
      </geometry>
    </collision>
  </link>

  <!-- 足端连接到虚拟FT链接 -->
  <joint name="RH_foot_fixed" type="fixed" dont_collapse="true">
    <origin xyz="0 0 0" rpy="0 0 0" />
    <parent link="RH_FT_wrist"/>
    <child link="RH_FOOT"/>
  </joint>

  <gazebo reference="RH_foot_fixed">
    <disableFixedJointLumping>true</disableFixedJointLumping>
  </gazebo>

  <!-- 右后腿FT传感器 -->
  <gazebo reference="RH_foot_fixed">
    <sensor name="rh_ft_sensor" type="force_torque">
      <always_on>true</always_on>
      <update_rate>1000</update_rate>
      <visualize>true</visualize>
      <topic>/ft_sensor/rh_wrench</topic>
      <force_torque>
        <noise>
          <type>gaussian</type>
          <force>
            <mean>0</mean>
            <stddev>0.01</stddev>
          </force>
          <torque>
            <mean>0</mean>
            <stddev>0.001</stddev>
          </torque>
        </noise>
      </force_torque>
    </sensor>
  </gazebo>

  <gazebo reference="RH_hip">
    <mu1>0.2</mu1>
    <mu2>0.2</mu2>
    <material>Gazebo/Turquoise</material>
  </gazebo>
  <gazebo reference="RH_thigh">
    <mu1>0.2</mu1>
    <mu2>0.2</mu2>
    <self_collide>0</self_collide>
    <material>Gazebo/Turquoise</material>
    <kp value="1000000.0"/>
    <kd value="100.0"/>
  </gazebo>
  <gazebo reference="RH_calf">
    <mu1>0.3</mu1>
    <mu2>0.3</mu2>
    <self_collide>1</self_collide>
  </gazebo>
  <gazebo reference="RH_FT_wrist">
    <mu1>0.3</mu1>
    <mu2>0.3</mu2>
    <self_collide>0</self_collide>
  </gazebo>
  <gazebo reference="RH_FOOT">
    <mu1>5.5</mu1>
    <mu2>5.5</mu2>
    <self_collide>1</self_collide>
    <material>Gazebo/Turquoise</material>
    <kp>10000000.0</kp>
    <kd>10000.0</kd>
    <maxVel>1.0</maxVel>
    <minDepth>0.001</minDepth>
  </gazebo>

  <!-- 添加执行器 -->
  <transmission name="LF_HAA_tran">
    <type>transmission_interface/SimpleTransmission</type>
    <joint name="LF_HAA">
      <hardwareInterface>hardware_interface/EffortJointInterface</hardwareInterface>
    </joint>
    <actuator name="LF_HAA_motor">
      <hardwareInterface>hardware_interface/EffortJointInterface</hardwareInterface>
      <mechanicalReduction>1</mechanicalReduction>
    </actuator>
  </transmission>
  <transmission name="LF_HFE_tran">
    <type>transmission_interface/SimpleTransmission</type>
    <joint name="LF_HFE">
      <hardwareInterface>hardware_interface/EffortJointInterface</hardwareInterface>
    </joint>
    <actuator name="LF_HFE_motor">
      <hardwareInterface>hardware_interface/EffortJointInterface</hardwareInterface>
      <mechanicalReduction>1</mechanicalReduction>
    </actuator>
  </transmission>
  <transmission name="LF_KFE_tran">
    <type>transmission_interface/SimpleTransmission</type>
    <joint name="LF_KFE">
      <hardwareInterface>hardware_interface/EffortJointInterface</hardwareInterface>
    </joint>
    <actuator name="LF_KFE_motor">
      <hardwareInterface>hardware_interface/EffortJointInterface</hardwareInterface>
      <mechanicalReduction>1</mechanicalReduction>
    </actuator>
  </transmission>
  <transmission name="LH_HAA_tran">
    <type>transmission_interface/SimpleTransmission</type>
    <joint name="LH_HAA">
      <hardwareInterface>hardware_interface/EffortJointInterface</hardwareInterface>
    </joint>
    <actuator name="LH_HAA_motor">
      <hardwareInterface>hardware_interface/EffortJointInterface</hardwareInterface>
      <mechanicalReduction>1</mechanicalReduction>
    </actuator>
  </transmission>
  <transmission name="LH_HFE_tran">
    <type>transmission_interface/SimpleTransmission</type>
    <joint name="LH_HFE">
      <hardwareInterface>hardware_interface/EffortJointInterface</hardwareInterface>
    </joint>
    <actuator name="LH_HFE_motor">
      <hardwareInterface>hardware_interface/EffortJointInterface</hardwareInterface>
      <mechanicalReduction>1</mechanicalReduction>
    </actuator>
  </transmission>
  <transmission name="LH_KFE_tran">
    <type>transmission_interface/SimpleTransmission</type>
    <joint name="LH_KFE">
      <hardwareInterface>hardware_interface/EffortJointInterface</hardwareInterface>
    </joint>
    <actuator name="LH_KFE_motor">
      <hardwareInterface>hardware_interface/EffortJointInterface</hardwareInterface>
      <mechanicalReduction>1</mechanicalReduction>
    </actuator>
  </transmission>
  <transmission name="RF_HAA_tran">
    <type>transmission_interface/SimpleTransmission</type>
    <joint name="RF_HAA">
      <hardwareInterface>hardware_interface/EffortJointInterface</hardwareInterface>
    </joint>
    <actuator name="RF_HAA_motor">
      <hardwareInterface>hardware_interface/EffortJointInterface</hardwareInterface>
      <mechanicalReduction>1</mechanicalReduction>
    </actuator>
  </transmission>
  <transmission name="RF_HFE_tran">
    <type>transmission_interface/SimpleTransmission</type>
    <joint name="RF_HFE">
      <hardwareInterface>hardware_interface/EffortJointInterface</hardwareInterface>
    </joint>
    <actuator name="RF_HFE_motor">
      <hardwareInterface>hardware_interface/EffortJointInterface</hardwareInterface>
      <mechanicalReduction>1</mechanicalReduction>
    </actuator>
  </transmission>
  <transmission name="RF_KFE_tran">
    <type>transmission_interface/SimpleTransmission</type>
    <joint name="RF_KFE">
      <hardwareInterface>hardware_interface/EffortJointInterface</hardwareInterface>
    </joint>
    <actuator name="RF_KFE_motor">
      <hardwareInterface>hardware_interface/EffortJointInterface</hardwareInterface>
      <mechanicalReduction>1</mechanicalReduction>
    </actuator>
  </transmission>
  <transmission name="RH_HAA_tran">
    <type>transmission_interface/SimpleTransmission</type>
    <joint name="RH_HAA">
      <hardwareInterface>hardware_interface/EffortJointInterface</hardwareInterface>
    </joint>
    <actuator name="RH_HAA_motor">
      <hardwareInterface>hardware_interface/EffortJointInterface</hardwareInterface>
      <mechanicalReduction>1</mechanicalReduction>
    </actuator>
  </transmission>
  <transmission name="RH_HFE_tran">
    <type>transmission_interface/SimpleTransmission</type>
    <joint name="RH_HFE">
      <hardwareInterface>hardware_interface/EffortJointInterface</hardwareInterface>
    </joint>
    <actuator name="RH_HFE_motor">
      <hardwareInterface>hardware_interface/EffortJointInterface</hardwareInterface>
      <mechanicalReduction>1</mechanicalReduction>
    </actuator>
  </transmission>
  <transmission name="RH_KFE_tran">
    <type>transmission_interface/SimpleTransmission</type>
    <joint name="RH_KFE">
      <hardwareInterface>hardware_interface/EffortJointInterface</hardwareInterface>
    </joint>
    <actuator name="RH_KFE_motor">
      <hardwareInterface>hardware_interface/EffortJointInterface</hardwareInterface>
      <mechanicalReduction>1</mechanicalReduction>
    </actuator>
  </transmission>

  <!-- ros_control plugin -->
  <gazebo>
    <plugin filename="liblegged_hw_sim.so" name="gazebo_ros_control">
      <robotNamespace>/</robotNamespace>
      <robotParam>legged_robot_description</robotParam>
      <robotSimType>legged_gazebo/LeggedHWSim</robotSimType>
    </plugin>
  </gazebo>
  <gazebo>
    <plugin filename="libgazebo_ros_p3d.so" name="p3d_base_controller">
      <alwaysOn>true</alwaysOn>
      <updateRate>1000.0</updateRate>
      <bodyName>base</bodyName>
      <topicName>ground_truth/state</topicName>
      <gaussianNoise>0</gaussianNoise>
      <frameName>world</frameName>
      <xyzOffsets>0 0 0</xyzOffsets>
      <rpyOffsets>0 0 0</rpyOffsets>
    </plugin>
  </gazebo>
</robot>